export const handleError = catchFn => ({
  use,
  error,
  result,
  args
}) => {
  try {
    if (error) {
      return {
        result: catchFn(error, args),
        use,
        args
      }
    } else {
      return { use, result, args }
    }
  } catch (error) {
    return { error, use, args }
  }
}
